Workbook

Sheet GRAPH

Sheet Budget
B3: 2025 ACTUAL | C3: 2025 PROJECTED | D3: 2026 ADOPTED
A4: MEMBER ASSESSMENT
A5: Per Quarter Per Lots - 110 Lots | B5: 457.001 | C5: =B5 -> 457.001 | D5: =(D8+D13)/110/4 -> 457.00473
A6: (a+b)/110
A8: Member Assessments | B8: 161477.44 | C8: =B8 -> 161477.44 | D8: =D11-D10-D9 -> 161479.08 | E8: a.
A9: Special Assessment | B9: 0 | C9: 0 | D9: 0
A10: Interest | B10: 0 | C10: 0 | D10: 0
A11: TOTAL OPERATING | B11: 161477.44 | C11: =C8 -> 161477.44 | D11: =D63 -> 161479.08
A12: RESERVES
A13: Assessments | B13: 39603 | C13: 38880 | D13: =D15-D14 -> 39603
A14: Interest | B14: 0 | C14: 7 | D14: 0
A15: TOTAL RESERVES | B15: 39603 | C15: =SUM(C13:C14) -> 38887 | D15: =D66 -> 39603
B16: 201080.44 | C16: =C11+C15 -> 200364.44 | D16: =D11+D15 -> 201082.08
A17: ADMINISTRATION
A18: CPA Fees | B18: 1000 | C18: 215 | D18: 1000
A19: Postage & Printing/Office Supplies | B19: 1450 | C19: 922.53 | D19: 1250
A20: Bank Charges/Coupons | B20: 707 | C20: 325 | D20: 400
A21: Attorney Fees | B21: 6500 | C21: 4050 | D21: 5000
A22: Management Fees | B22: 12940 | C22: 12940 | D22: 13324.08
A23: Misc. Administrative Expense | B23: 1300 | C23: 162 | D23: 500
A24: Annual Corporate Report | B24: 62 | C24: 62 | D24: 62
A25: Insurance -Bldg/Other | B25: 17210.44 | C25: 13076.19 | D25: 15000
A26: TOTAL ADMINISTRATION | B26: 41169.44 | C26: =SUM(C18:C25) -> 31752.72 | D26: =SUM(D18:D25) -> 36536.08
A28: BUILDING AND GROUNDS
A29: Grounds Maintenance Contract | B29: 51500 | C29: 57144 | D29: 58858
A30: Misc Grds Landsc | B30: 5000 | C30: 4885.71 | D30: 6000
A31: Tree Trimming | B31: 1000 | C31: 1000 | D31: 1000
A32: Grounds /Plantings | B32: 2500 | C32: 0 | D32: 1500
A33: Mulch | B33: 3000 | C33: 4990 | D33: 5000
A34: Irrigation Repairs | B34: 2500 | C34: 5006.88 | D34: 2500
A35: Lake Maintenance | B35: 5000 | C35: 2520 | D35: 3500
A36: Pump Maintenance | B36: 2000 | C36: 115 | D36: 500
A37: TOTAL BLDG & GROUNDS | B37: 72500 | C37: =SUM(C29:C36) -> 75661.59 | D37: =SUM(D29:D36) -> 78858
A39: MAINTENANCE
A40: Misc Repair | B40: 1000 | C40: 2015 | D40: 1500
A41: Fire Safety | B41: 350 | C41: 0 | D41: 265
A42: Pest Control/Cabana | B42: 500 | C42: 0 | D42: 400
A47: Cabana Maint | B47: 775 | C47: 0 | D47: 400
A48: Fence/Wall Maintenance | B48: 600 | C48: 0 | D48: 400
A49: Gate Maint Contract | B49: 7500 | C49: 8171 | D49: 8000
...

Sheet Graph #s
A1: ADMIN | C1: =(D1/D7) -> 0.18169734 | D1: =Budget!D26 -> 36536.08
A2: BLDG & GROUNDS | C2: =(D2/D7) -> 0.39216821 | D2: =Budget!D37 -> 78858
A3: MAINTENANCE | C3: =(D3/D7) -> 0.13917202 | D3: =Budget!D56 -> 27985
A4: UTILITIES | C4: =(D4/D7) -> 0.090012994 | D4: =Budget!D62 -> 18100
A5: RESERVES | C5: =(D5/D7) -> 0.19694942 | D5: =Budget!D66 -> 39603
C7: =SUM(C1:C5) -> 1 | D7: =SUM(D1:D5) -> 201082.08
